Workbook

Sheet Лист3
A4: 09,03,2022 | B4: MAMATOVA YULDUZ DAVLATOVNA | C4: 98529134 | F4: 99 212 73 78 Iqush og`a Beruniy | H4: 2 | J4: 4
A5: 20,02,2022 | B5: YUSUPOVA NAZOKAT OTAXONOVNA( Otabek ) | C5: 40509212 | H5: 1 | J5: 77 028 77 81
A6: 10,03,2022 | B6: Jo`shqin og`a | F6: madaniyat | G6: 20 mln Jo`shqin og`ani o`zi | H6: 20 | J6: 9
A7: 23,03,2022 | F7: Nurafshon | G7: Nurafshon 77 033 91 01 karuch zavod | H7: =18.8*2 -> 37.6 | K7: 2
A8: 25,03,2022 | B8: MAMIYEVA ALIYAJAN MUMINOVNA | C8: 26706601 | E8: 20 | F8: Tozabozor | G8: Tozabozor Egamov Baxtiyor
A9: 25,03,2022 | B9: JUMANIYAZOV MARKS XO‘JANIYOZOVICH | C9: 75591482 | E9: 23 | F9: Madaniyat | G9: Madaniyat
A10: 29,03,2022 | B10: ATABAYEV GANJABOY JUMANAZAROVICH | C10: 97198640 | E10: 23 | F10: Tozabozor | G10: 32 mln rulli Tozabozor sahrtnomaga qarab turibdi 97 600 14 65
A11: 30,03,2022 | B11: OLLASHOVA DILRABO QURAMBOYEVNA | C11: 69346425 | E11: 18 | F11: Yangiariq | G11: Yangiariq 97 753 7313 97 601 95 95
A12: 30,03,2022 | B12: MADAMINOVA GULRUX TO‘LQIN | C12: 29675034 | E12: 22 | F12: Г | G12: Manaviyat 99 752 34 30
A13: 30,03,2022 | B13: XUDAYBERGANOV JO‘RABEK BOBONAZAROVICH | C13: 41699722 | D13: navbatda | E13: 22 | F13: Nurli Hayot | G13: Nurli hayot 94 860 58 87 | L13: 23,05,2023
A14: 31,03,2022 | B14: BAKIYEV HAMDAMBEK TOJIBOYEVICH | C14: 11498321 | E14: 22.5 | F14: 22.5 | G14: Nurafshon klient 99 122 61 52 | L14: 30,05,2023
A15: 31,03,2022 | B15: JUMANAZAROV NIZOMJON OZOD O‘G‘LI | C15: 30183671 | F15: Qalajiqala | G15: Qalajiqala 99 175 55 15
A16: 31,03,2022 | B16: JUMANAZAROV SAPARBOY MATCHONOVICH | E16: 25 | F16: madaniyat | G16: Mirzoxid og`a | J16: 2
A17: 31,03,2022 | B17: JABBAROV ISLOMBEK ABDULLAYEVICH | C17: 91142276 | E17: 25 | F17: madaniyat | G17: Mirzoxid og`a | J17: 3
A18: 31,03,2022 | B18: ABDULLAYEV DIYORBEK | C18: 19605444 | D18: navbatda | F18: madaniyat | G18: Tozabozor 97 091 17 95 | J18: 4
A19: 31,03,2022 | B19: MATYAQUBOV QODAMBOY YULDASHOVICH | C19: 81026374 | F19: madaniyat | G19: Toyir og`a | J19: 5 6
A20: 01,04,2023 | B20: JUMABOYEV HASANBOY QAHRAMON O‘G‘LI | C20: 72673422 | F20: Nurafshon | G20: Nurafshon 94 312 50 69 | L20: 04,05,2023
A21: 01,04,2023 | B21: XO‘JANIYOZOV MARDON BAXTIYOROVICH | C21: 29829339 | F21: madaniyat | G21: Nurafshon 93 467 15 14 | J21: 7 | L21: 04,05,2023
A22: 01,04,2023 | B22: OTAJONOVA GULYOR HAYITBOY QIZ | C22: 67505033 | E22: 25 | F22: madaniyat | G22: Qalajiqala 94 112 77 66 | J22: 8
A23: 02,04,2023 | B23: TILLAYEV BOZORBOY RO‘ZIYEVICH | C23: 34772565 | F23: Oq tepa | G23: Oq tepa 99 176 86 86
A24: 02,04,2023 | B24: BABAJANOV OG‘ABEK RASHID O‘G‘LI | C24: 92554392 | E24: 33 | F24: Yangiqadam | G24: Yangiqadam 95 589 24 95
A25: 02,04,2023 | B25: MIRZAYEV RAXIMBERDI XUDASHUKUROVICH | C25: 40316239 | F25: Nurafshon | G25: Nurafshon | L25: 04,05,2023
A26: 02,04,2023 | B26: BEKMETOV SAPARBOY | C26: 27780518 | D26: navbatda | E26: 25 | F26: Qumbodoq | G26: Mirzoxid og`a
A27: 02,04,2023 | B27: MATYOQUBOV KOMILJON IBADULLAYEVICH | C27: 56211981 | E27: 23 | F27: Qalajiqala | G27: Qalajiqala
A28: 02,04,2023 | B28: QO‘ZIBAYEVA HAYOTXON SAFARBAYEVNA | C28: 15215403 | D28: benzin | E28: 33 | F28: Dexqonobod | G28: 88 857 00 29 33 mln matsakil Benzin Dexqonobod MFY
A29: 03,04,2023 | B29: BEKNAZAROV DAVRANBEK IBRAHIMOVICH | C29: 46213614 | E29: 25 | F29: Ashxobod | G29: Ashxobod
A30: 05,04,2023 | B30: MATCHANOV ODILBEK BOBOXONOVICH | C30: 38951800 | E30: 33 | F30: To`pchi | G30: Donyor oga to`pchi
A31: 05,04,2023 | B31: QURBONOVA FAROG‘AT TOHIROVNA | C31: 30306539 | E31: 25 | F31: Tozabozor | G31: Tozabozor 97 721 07 86
A32: 05,04,2023 | B32: OLLAMOVA GULBAXOR UMAROVNA | C32: 12539075 | D32: 28 ming soliq qarzi | E32: Mol mulki | F32: Oq tepa | G32: Oq tepa 93 744 40 90
A33: 06,04,2023 | B33: SAIDOVA GULNOZA SHONAZAROVNA | C33: 63804637 | E33: 20 | F33: Yangiqadam | G33: Yangiqadam
A34: 06,04,2023 | B34: QURBANBAYEV UKTAMBOY RAXIMBOYEVICH | C34: 95583528 | F34: Uzumzor | G34: Uzumzor 99 079 98 50
A35: 06,04,2023 | B35: AMINOV IXTIYOR | C35: 99087510 | F35: Tozabozor | G35: Tozabozor Qosim og`a 97 456 9002 | L35: 13,05,2023
A36: 06,04,2023 | B36: AMIROV NIZAMATDIN | F36: Qaraqalpoq | G36: Qaraqalpoq
A37: 07,04,2023 | B37: BOBOJONOV KAMOL | C37: 40665497 | E37: 24 | F37: madaniyat | G37: Xurriyat 31 53 236 93 287 84 36 | J37: 1 shapka
A38: 07,04,2023 | B38: MAVLONOV JABBORBERDI YULDOSHOVICH | C38: 57135624 | E38: 33 | F38: madaniyat | G38: 97 791 83 88 | J38: benzin
A39: 07,04,2023 | B39: YUSUPOVA GULNORA AXMEDOVNA | C39: 43037916 | F39: Ustalar | G39: 97 452 73 84 Ustalar Sarvar og`a | J39: 1,5 tonna
A40: 07,04,2023 | B40: ALLABERGANOVA GAVHAR KARIMBOYEVNA | C40: 57656509 | D40: 108 soliq qarz | F40: Xonqa | G40: Xonqa 93 854 64 27 99 184 08 39 | J40: 0,6 liq
A41: 07,04,2023 | B41: SADULLAYEVA ODINA QO‘ZIBAYEVNA | C41: 25491838 | E41: 33 | F41: madaniyat | G41: Soxibkor 99 333 74 13 | J41: rulli
A42: 07,04,2023 | B42: RAXIMOVA MARHAMAT NURULLAYEVNA | C42: 68347276 | D42: 16,05,2023 | E42: rasm | F42: Nurafshon | G42: Izzatni tanishlari 99 038 66 00 | L42: 30,05,2023
A43: 09,04,2023 | B43: JUMABOYEV SAN’ATBEK KUROMBOYEVICH | C43: 36748622 | D43: r | F43: Oq Oltin | G43: Oq Oltin 94 114 76 83 99 163 79 76 94 310 79 76
...

Sheet Qoraqalpoq 
A2: 2022 yil | B2: XUDAYBERGENOV RAVSHANBEK DAVLATOVICH | E2: 30 млн матсакил Журабек ога | F2: 30 | H2: e | I2: 2.5
A3: 1 | B3: SHEROV SEVINDIK KURBANBAYEVICH | C3: 88888888 | F3: 31 | H3: e
A4: 2 | B4: ZARIPOVA DONOXON BEKNAZAR QIZI | F4: 26 | H4: e
A5: 3 | B5: BABAJANOVA SHAXNAZA BAZARBAYEVNA | F5: 33 | H5: b
A6: 4 | B6: SAPARBAYEVA KUNDUZ YERKABAYEVNA | F6: 33 | H6: b
A7: 5 | B7: YESHIMBETOV AKBAR YULDASHBAYEVICH | F7: 33 | H7: b
A8: 6 | B8: SAPARBAYEV ALISHER XUDAYBERGENOVICH | F8: 30 | H8: b
A9: 7 | B9: SABIROVA SANABAR DJUMABAYEVNA | F9: 30 | H9: b | J9: ariza berilmagan | O9: 20 mln berildi Bonus | P9: 27,,02,2023
A10: 8 | B10: RAMANBERGENOV ALLAMBERGAN RAVSHANBEK O‘G‘LI | F10: 31 | H10: e | O10: 10 mln 16,03,2023
A11: 9 | B11: MADAMINOVA ALMAGUL XAITBAYEVNA | F11: 30 | H11: b | O11: 10 mln 27,03,2023
A12: 10 | B12: JABBIYEV XAMID ALLAMBERGENOVICH | F12: 25 | H12: e | O12: 50 mln 05,04,2023
A13: 11 | B13: MOLDABAYEV ADIL ABDIMURATOVICH | F13: 30 | H13: b | O13: 10 mln 01,05,2023
A14: 12 | B14: BEKIMBETOV SEYTNAZAR FAYZULLAYEVICH | F14: 30 | H14: b | O14: 10mln 22,05,2023
A15: 13 | B15: MUMINOVA XOSIYAT KURBANBAYEVNA | F15: 31 | H15: e
A16: 14 | B16: XUDAYBERGENOVA MASTURA URAZBAYEVNA | F16: 33 | H16: b
A17: 15 | B17: ZARLIKOVA ROZA MURATBAYEVNA | F17: 30 | H17: b
A18: 16 | B18: KADIROVA GULSANAM YEGAMBERGANOVNA | F18: 30 | H18: b | J18: kredit shartnoma
A19: 17 | B19: KURBANBAYEV BAXRAM BERDIMURATOVICH | F19: 33 | H19: b | J19: kredit shartnoma
A20: 18 | B20: AKMANOV AZAMAT JUMABAYEVICH | F20: 33 | H20: b
A21: 19 | B21: DJABBARBERGENOV OYBEK NURKENOVICH | F21: 30 | H21: b
A22: 20 | B22: MATSAPAYEVA ZULFIYA KAMALADDINOVNA | F22: 31 | H22: e
A23: 21 | B23: ZaRLIQOV OBIDJON | F23: 25
A24: 22 | B24: BABANIYAZOV ERGASH XUSANOVICH | F24: 31
A25: 23 | B25: ABDREYMOV MAXAMMETJAN ABDREYMOVICH | F25: 31
A26: 24 | B26: MATNAZAROV FAXRATDIN ACHILOVICH | F26: 33
A27: 25 | B27: OSPANOVA BAYAN ROZUMBAYEVNA | F27: 33
A28: 26 | B28: ATADJANOV OBODJON FARXADOVICH | F28: 29
A29: 27 | B29: RAMETOV ILYAS ANVAROVICH | F29: 31
A30: 28 | B30: ISAKOVA ILMIRA RUSTAMOVNA | F30: 25
A31: 29 | B31: RADJAPBAYEV OTAMURAD YULDASHOVICH | F31: 29
A32: 30 | B32: YESHIMBETOVA OYDIN TURABAYEVNA | F32: 29
A33: 31 | B33: PRIMBETOVA TUXTA URAZBAYEVNA | C33: r | F33: 25
A34: 32 | B34: REYIMOV MATNAZAR TURABAYEVICH | F34: 33 | H34: 31
A35: 33 | B35: BABASHOV UMRBEK BALKIBAYEVICH | G35: 2 | H35: 31
A36: 34 | B36: YULDASHOV QAMAR SHERIPBAYEVICH | F36: 29
A37: 35 | B37: KOZIBAYEVA NAVBAXOR SABIROVNA
A38: 36 | B38: ATAJANOV AXMADJON RUSTAMOVICH | F38: 29
A39: 37 | B39: ABDULLAYEVA GUZAL ATAXANOVNA | F39: 29
A40: 38 | B40: RAXIMBAYEV YO‘LDOSH IBADULLAYEVICH | G40: 0 | H40: 25 | I40: Jonibek og` a
A41: 39 | B41: SABUROV KUDRAT JIYEMURATOVICH
...

Sheet QAraqalpoq Jonibek og`a 
B3: KURBANALIYEVA MARAL | D3: b33
B4: Erkaboeva Mexribon | D4: b30
B5: RAXIMBAYEV YO‘LDOSH IBADULLAYEVICH | C5: 0 | D5: e | E5: 25
B6: SAPAROV XALMURAT GAIPNAZAROVICH | C6: =45+21-33 -> 33 | D6: 38594035
B7: Nurjonov Ilxom | D7: 33 | E7: Men tarafdan olingan
B8: Sabirova Adolat | D8: 24
B9: PRIMBETOVA GULSHAD AKNAZAROVNA | D9: 33 | E9: Jo`rabek tarafdan olingan
B10: KURBANBAYEV XASANBAY ULUG‘BEK O‘G‘LI | M10: 10
B11: SHUKURULLAYEVA ASALXON AXMAD QIZI
C12: 23
B13: O`razbayev Ibadulla 32 mln rulli | C13: 32 | M13: 4.7
D14: 1 | E14: 20lik | M14: 52.5
M15: 61.5
M16: 270.5
M17: 304.6
M18: 24
H19: 54 | M19: 60
H20: 87 | M20: 9.3
H21: 200 | M21: 0.9
M22: 1.74
M23: 2.8
M24: 15
M25: 4.5
M26: 4.5
M27: 4
M28: 6.3
M29: 25
M30: 25
M31: 20
M32: 20
M33: 287.5
... M46: 56

Sheet МХК
D3: Хоразм вилояти Богот тумани Ок Олтин МФЙ
A5: Уч ғилдиракли юк мотороллер | B5: 08711001001000000 08704001001000000 | C5: 21.23.25.30.31.32.33 | D5: Размер каретки:""2000*1300mmгрузовой транспорт"Задний мост:Мост CHANGAN с повышенной мощностьюПередняя шина: 5.00-12 Задняя шина: 5.00-12Двигатель: 200cc Расход топлива на 100 кмРазмер каретки:""2000*1300mmгрузовой транспорт"Задний мост:Мост CHANGAN с повышенной мощностьюПередняя шина: 5.00-12 Задняя шина: 5.00-12Двигатель: 200cc Расход топлива на 100 кмРазмер каретки:""2000*1300mmгрузовой транспорт"Задний мост:Мост CHANGAN с повышенной мощностьюПередняя шина: 5.00-12 Задняя шина: 5.00-12Двигатель: 200cc Расход топлива на 100 км
A6: Карчер | B6: 8.424002e+15 | C6: 10. 12.5 15 | D6: Мойка высокого давления RTRMAX RTM7015 Керамический поршень Шланг длиной 10 м, устойчивый к давлению и нагреванию Байпасная технология, предотвращающая перегрузку насоса и двигателя давлением Тепловая система, предотвращающая перегрев электродвигателя Бесшумная и плавная работа Области использования Напряжение сети 220 — 230 В Частота тока 50 Гц Мощность 3 кВт Скорость вращения 1400 об/мин Максимальное давление 150 бар Расход воды 480 л/час Вес 55 Кг Гарантия 6 месяцев Brand RTRMAX
A7: Музқаймок ишлаб чикариш ускунаси | B7: 08459001006000000 0841800101300 | C7: 25 - 33 mln | D7: Улгуржи(оптом) нархларда.Хитойнинг энг оригинал завод махсулотлари. Узбекистон буйича етказиб бериш хизматлари,1 йиллик сервиз хизматлари борУлгуржи(оптом) нархларда.Хитойнинг энг оригинал завод махсулотлари. Узбекистон буйича етказиб бериш хизматлари,1 йиллик сервиз хизматлари борУлгуржи(оптом) нархларда.Хитойнинг энг оригинал завод махсулотлари. Узбекистон буйича етказиб бериш хизматлари,1 йиллик сервиз хизматлари борУлгуржи(оптом) нархларда.Хитойнинг энг оригинал завод махсулотлари. Узбекистон буйича етказиб бериш хизматлари,1 йиллик сервиз хизматлари бор
A8: Тикиш машиналари | B8: 844700100600 | C8: 4,4 4,5 5 5,5 5,9 6 6,5 7 7,5 8,25 9 10 15 | D8: Швейная машинка JACK F4 "JK-F 4" Высокоскоростная прямострочная швейная машинка "JK-F 4" Одноигольная машина челночного стежка с плоской платформой, нижним транспортером и встроенным серводвигателем. Преимущества швейной машины: Автоматическая система смазки Подсветка рабочей зоны Встроенный в голову серводвигатель с блоком управления Применение швейной машины: Для стачивания легких и средних материалов
A9: Автомабил ювиш учун пуркагичли флакон | B9: 0841300200300 | C9: 3 4 5 | D9: Пеногенератор просто, эффективно и быстро преобразует моющее (химическое) вещество в пену, которая затем наносится на очищаемую поверхность. Используются пеногенераторы для очистки транспортных средств и различных сооружений, для работы в пищевой и перерабатывающей промышленности, для дезинфекции оборудования, производственных площадей.МАТЕРИАЛ БАКА крашенная сталь ОБЪЕМ БАКА 95 л. РАБОЧЕЕ ДАВЛЕНИЯ 6 бар МАКСИМАЛЬНОЕ ДАВЛЕНИЕ 8 бар ВЕРТИКАЛЬНОЕ ИСПОЛНЕНИЕ есть МАНОМЕТР есть ИНДИКАТОР УРОВНЯ есть ПРЕДОХРАНИТЕЛЬНЫЙ КЛАПАН есть БРЕНД
A10: Чангюткич | B10: 0850800100200 | C10: 3 4 5 8 10 | D10: Качественный и профессиональный пылесос для сухой и влажной уборки (пылеводосос) предназначен для сбора сухого или влажного мусора, воды и жидкой грязи. МОЩНОСТЬ 3600 Вт ОБЪЕМ БАКА 80 л. ПОТОК ВОЗДУХА 106 л/сек. НАПРЯЖЕНИЕ СЕТИ 220В ФУНКЦИИ УБОРКИ Влажная/сухая ДЛИНА КАБЕЛИ
A11: Компрессор | B11: 8.414002e+15 | C11: 2 3 4 4,5 5 8 10 15 | D11: Единица товара: Штука Вес, кг: 24,83 Длина, мм: 650 Ширина, мм: 275 Высота, мм: 620 Компрессор; Ресивер; Универсальное быстродействующее соединение; Обрезиненная рукоятка; Упаковка. Единица товара: Штука Вес, кг: 24,83 Длина, мм: 650 Ширина, мм: 275 Высота, мм: 620 Компрессор; Ресивер; Универсальное быстродействующее соединение; Обрезиненная рукоятка; Упаковка. Единица товара: Штука Вес, кг: 24,83 Длина, мм: 650 Ширина, мм: 275 Высота, мм: 620 Компрессор; Ресивер; Универсальное быстродействующее соединение; Обрезиненная рукоятка; Упаковка.
A12: Печка | B12: 8.417002e+15 | C12: 20 22 24 25 33 | D12: Печка Хитойники 380 В да ишлайди Гарантия 3 йил промой скаладдан таркатамиз Бизда хаммаси арзон ва янги Печка Хитойники 380 В да ишлайди Гарантия 3 йил промой скаладдан таркатамиз Бизда хаммаси арзон ва янгиПечка Хитойники 380 В да ишлайди Гарантия 3 йил промой скаладдан таркатамиз Бизда хаммаси арзон ва янги Печка Хитойники 380 В да ишлайди Гарантия 3 йил промой скаладдан таркатамиз Бизда хаммаси арзон ва янгиПечка Хитойники 380 В да ишлайди Гарантия 3 йил промой скаладдан таркатамиз Бизда хаммаси арзон ва янги Печка Хитойники 380 В да ишлайди Гарантия 3 йил промой скаладдан таркатамиз Бизда хаммаси арзон ва янги
A13: Жатки | B13: 8.432003e+15 | C13: 10 - 33 | D13: Мотоблоги билан бирга уриш ва ер хайдаш учун мулжалланган махсус спесжатка сифатли техникалар харит килишни хохлайсизми унда бизга мурожат килинг йитказиб бериш хизмати хам мавжут Ишлаб чикарилган давлат - Хитой Энг кам микдори - 1 та Яроклик муддати - 3 йил Қуввати -12 от кучи Техник параметрлари-Мотокултиватор 13 л,с. Бензин
A14: Мотоблок | B14: 843200300100 | C14: 10 -33 | D14: Ишлаб чикарилган давлат - Хитой Энг кам микдори - 1 та Яроклик муддати - 3 йил Қуввати -12 от кучи Техник параметрлари-Мотокултиватор 13 л,с. Бензин
A15: Cув тозалаш ускуна | B15: 08421002005000001 | C15: 27 - 33 | D15: Сув тозалаш тизими тўплами. Теплица. парник. иссиқхоналар: Мой сам. автомобилларни ювиш шахобчалари: Ахоли учун тоза ичимлик сувлари ишлаб чиқариш учун барча турдаги сув тозалаш тизимлари!!! Тескари осмос технологияси асосидаги 5 боскичли сув тозалаш системаси. Ишлаб чикариш куввати – 500 литр/соат. Боскичлари: 1. Механик фильтр, фильтрловчи элемент – кварц қуми 2. Сорбцион фильтр, фильтрловчи элемент – фаол кўмир 3. Сув юмшатиш фильтри, фильтрловчи элемент – катионит 4. Нозик тозалаш фильтри, фильтрловчи элемент – полипропилен картридж 5. Тескари осмос тизими, фильтрловчи элемент – мембрана Энергия истеъмоли – 1.9 кВт, 220V/50HZ. Ишчи харорат: +10С… +40С
A16: Кесувчи арра ускунаси | B16: 08461001005000000 2 | C16: 30 31 32 33 | D16: (РУС) Компания: (РУС) Модель: (РУС) Макс. длина распила: (РУС) Макс. ширина распила: (РУС) Радиус основной пилы: (РУС) Радиус второй пилы: (РУС) Скорость вращения основной пилы: (РУС) Скорость второй пилы: (РУС) Толщина распила: (РУС) В комплекте: (РУС) WoodTech Working Machinary (Китай) (РУС) MJ6132YT-MJ45 (РУС) 3000 мм (РУС) 1250 мм (РУС) 330/30 мм (РУС) 120/20 мм (РУС) 4000-6000 раз/мин (РУС) 7000-8000 раз/мин (РУС) 80 мм (РУС) пылесос , запасная пила
A17: Хомир коргич | B17: 843800200200 | C17: 8 10 12 | D17: юкори сифатга эга бўлган занга чидамли темирдан ясалган хамир қориш машинаси сотилади сифатига 100 фоиз кафолат берилади юкори сифатга эга бўлган занга чидамли темирдан ясалган хамир қориш машинаси сотилади сифатига 100 фоиз кафолат берилади юкори сифатга эга бўлган занга чидамли темирдан ясалган хамир қориш машинаси сотилади сифатига 100 фоиз кафолат берилади юкори сифатга эга бўлган занга чидамли темирдан ясалган хамир қориш машинаси сотилади сифатига 100 фоиз кафолат берилади
A18: Музлаткич | B18: 8.418001e+15 | C18: 7,5 8 10 12 | D18: • Телефон Кисела Хар хил маделларидан бор • Ишлаш тизими Но Фрост воздушный • Електор тежовчи А+ класс • Без табло с табло • Бойи 1.75см Ени 60см • 2 камерали • 3 Йил сервис гарантия + 10 йил маторига гарантия • Доставка Бепул Кун давомида йетказиб бериладиЮкори сифатили музкаймок ва шу каби сут махсулотларини саклаш учун 100 сифатга эга махсулот сифати кафолат берилади Юкори сифатили музкаймок ва шу каби сут махсулотларини саклаш учун 100 сифатга эга махсулот сифати кафолат берилади Юкори сифатили музкаймок ва шу каби сут махсулотларини саклаш учун 100 сифатга эга махсулот сифати кафолат берилади Юкори сифатили музкаймок ва шу каби сут махсулотларини саклаш учун 100 сифатга эга махсулот сифати кафолат берилади Юкори сифатили музкаймок ва шу каби сут махсулотларини саклаш учун 100 сифатга эга махсулот сифати кафолат берилади Юкори сифатили музкаймок ва шу каби сут махсулотларини саклаш учун 100 сифатга эга махсулот сифати кафолат берилади
A19: Авто кўтаргич | B19: 8.425001e+15 | C19: 24 25 26 | D19: 2-х стоечный подъемник Launch TDY-2D40M с моторчиком 220v и 380v. Имеется 3.5Т также 4Т.2-х стоечный подъемник Launch TDY-2D40M с моторчиком 220v и 380v. Имеется 3.5Т также 4Т.2-х стоечный подъемник Launch TDY-2D40M с моторчиком 220v и 380v. Имеется 3.5Т также 4Т.2-х стоечный подъемник Launch TDY-2D40M с моторчиком 220v и 380v. Имеется 3.5Т также 4Т.2-х стоечный подъемник Launch TDY-2D40M с моторчиком 220v и 380v. Имеется 3.5Т также 4Т.
A20: Электр перфоратор | B20: 0846700100200 | C20: 2 3 4 5 | D20: PowerMaxx BS Basic Set * Mobile Workshop (Аккумуляторная дрель-шуруповерт, мобильная мастерская) Напряжение аккумулятора:10.8 В Макс. мягкий крутящий момент:17 Нм Макс. жесткий крутящий момент:34 Нм Диаметр сверления в стали:10 мм д. сверления в мягкой древесине:18 ммPowerMaxx BS Basic Set * Mobile Workshop (Аккумуляторная дрель-шуруповерт, мобильная мастерская) Напряжение аккумулятора:10.8 В Макс. мягкий крутящий момент:17 Нм Макс. жесткий крутящий момент:34 Нм Диаметр сверления в стали:10 мм д. сверления в мягкой древесине:18 мм
A21: Товуқ | B21: 0015500100100 | C21: 50 ming | D21: Брама жожалари сотилади конни 100 % тоза ота онасиниям суратини куришингиз мумкин 1 хафталигдан бошлаб 1 йошгача бор Тоза қон 40 кунлик ПАЛИВИЙ жўжалар сотилади. Брама жожалари сотилади конни 100 % тоза ота онасиниям суратини куришингиз мумкин 1 хафталигдан бошлаб 1 йошгача бор Тоза қон 40 кунлик ПАЛИВИЙ жўжалар сотилади. Брама жожалари сотилади конни 100 % тоза ота онасиниям суратини куришингиз мумкин 1 хафталигдан бошлаб 1 йошгача бор Тоза қон 40 кунлик ПАЛИВИЙ жўжалар сотилади. Брама жожалари сотилади конни 100 % тоза ота онасиниям суратини куришингиз мумкин 1 хафталигдан бошлаб 1 йошгача бор Тоза қон 40 кунлик ПАЛИВИЙ жўжалар сотилади.
A22: Чувалчанг | B22: 199001007000000 | C22: 0,5 | D22: Биогомус таййорлаш ва даромад олиш учун кулай. Калифорния Кизил ёмгир чувалчанги. Табиий биогумос ишлаб чикаради. Бир квадрати 500000 сум. Калифорнийский черви. 1 шт 500000 сум.Биогомус таййорлаш ва даромад олиш учун кулай. Калифорния Кизил ёмгир чувалчанги. Табиий биогумос ишлаб чикаради. Бир квадрати 500000 сум. Калифорнийский черви. 1 шт 500000 сум.Биогомус таййорлаш ва даромад олиш учун кулай. Калифорния Кизил ёмгир чувалчанги. Табиий биогумос ишлаб чикаради. Бир квадрати 500000 сум. Калифорнийский черви. 1 шт 500000 сум.
A23: Контейнер | B23: 8.609001e+15 | D23: Контейнер под офис. Ест наличе. Ofis uchun tayyor konteynerlar Devori mdf dekor Eshigi ichi mdf tashqi tomoni temir Romi akfa plast 6000 trio Patalogi plastik Poli linolim Elektrikasi tayyo
A24: Кондитсинер | B24: 0841500100100 | D24: Мощность охлаждения - 9500 Btu Мощность обогрева - 11000Btu Расход электроэнергии - 0,55 кВт Обслуживаемая площадь - 30 м2 Обслуживаемая площадь - 90 м3 Колличество фриона - 675 гр. Фрион - R32 Расход воздуха - 620 Low Voltage 115V-265V Экономия до 60% электроэнергии Скрытый Led Display Компрессор GMCC Toshiba 10 лет гарантии на компрессор 3 года сервисного обслуживания
A25: Компютер | B25: 8.471001e+15 | D25: ntel Core i7-10700T 2.0 GHz (up to 4.3 GHz) 8C 35 W / 8GB (1x8GB) DDR4 2666 SODIMM / 1TB 7200RPM 2.5" HDD / 9.5mm DVD-Writer / 23.8" (54.6 cm) Full HD (1920 x 1080) / Intel UHD Graphics 630 / Intel 9560 ac 2x2 nvP +Bluetooth 5 WW / FreeDOS / One Years Warranty / Black / USB Keyboard and Mouse Несмотря на то, что моноблоки появились давно и потеряли свою актуальность из-за пришедших взамен ноутбуков, развитие информационных технологий позволило им снова возродиться. Моноблок представляет собой компьютер, который встроен в корпус монитора. Удобство моноблоков в том, что они занимают мало свободного пространства и являются миниатюрной частью интерьера. На этом устройстве полностью отсутствуют провода, кроме сетевого провода, что значительно облегчит вам задачу переносить его куда-либо.
A26: Принтер | B26: 844300100100 | D26: A4 Печать фотографий есть Количество цветов 6 Минимальный объем капли 1.5 пл Печать без полей есть Максимальное разрешение для цветной печати 5760x1440 dpi Скорость печати 37 стр/мин (ч/б А4), 38 стр/мин (цветн. А4) Время печати 10x15 см (цветн.) 12 с планшетный Тип датчика контактный (CIS) Максимальный формат оригинала A4 Максимальный размер сканирования 216x297 мм Глубина цвета 24 бит Разрешение сканера 1200x2400 dpi 64-300 г/м2 Печать на: карточках, пленках, этикетках, фотобумаге, CD/DVD, глянцевой бумаге, конвертах, матовой бумаге Ресурс цветного картриджа/тонера 1800 страниц Ресурс ч/б картриджа/тонера 1800 страниц Количество картриджей 6 Тип картриджа/тонера черный C13T67314A, голубой C13T67324A, пурпурный C13T67334A, желтый C13T67344A, светло-голубой C13T67354A, светло-пурпурный C13T67364A Система непрерывной подачи чернил есть
A27: Стол | B27: 940300300100 | D27: Стильный и эргономичный стол, станет важным элементом интерьера. Просторная поверхность стола позволяет удобно разместить как компьютерное оборудование, так и канцелярские принадлежности. Под столешницей расположены выдвижные ящики для хранения мелочей. Изделие выполнено из высококачественного и экологичного материала – МДФ. Все края обработаны ударопрочной кромкой ПВХ, которая значительно увеличивает срок эксплуатации изделия. Для сборки изделия используется фурнитура ведущих мировых производителей. Заказывайте по доступным ценам компьютерный стол от производителя
A28: Комплект стол стуллари билан | B28: 0940300301200 | D28: Представляем вашему вниманию стильные и современные офисные кресла от "FurniGlass". Офисные кресла выполнены из высококачественной кожи, которая имеет стойкость к истиранию и постарению. Благодаря современному и стильному дизайну, офисные кресла в интерьер любого помещения и с любой мебелью.
A29: Балансировка | B29: 8.542001e+15 | D29: Диаметр дисков 10”-26”Автоматический ввод двух параметров колеса – расстояние до колеса, диаметр. Размер ширины диска вводиться в ручную. Система Direct 3D – точное прямое измерение геометрии ALU – дисков. 22 “ LED монитор Модель класса БИЗНЕС с интеллектуальным приводом. Отличают удобство в эксплуатации, простота и надежность. Информативный LCD-монитор обеспечивает комфортную работу на станке. Легкость в освоении и обслуживании: наглядное представление информации при работе - экраны подсказок доступны в любой момент - текстовое меню настроек - пошаговые инструкции по калибровке - речевое сопровождение Дополнительные функции: Оптимизация положения "шина-диск". Для уменьшения массы устанавливаемых грузов возможно проведение оптимизации «шина-диск». При оптимизации тяжелые участки диска и шины перемещаются на противоположные стороны, что позволяет снизить суммарный дисбаланс колеса. - «Невидимый груз» – SPLIT. Для сохранения внешнего вида дорогого диска мы предлагаем решение – переместить груз за спицы. Функция SPLIT разделит груз на два так, что они окажутся за спицами. ПАРАМЕТРЫ Макс. масса колеса, кг 65 Макс. диаметр диска, дюйм 26 Макс. ширина диска, дюйм 20 Макс. диаметр колеса, мм 800 Точность, г 1 Диаметр вала, мм 40 Дисплей LCD 19 Напряжение в сети 220В Масса, кг 85 Габаритные размеры, мм 915 x 1290 x 1330 Цвет Синий / красный
A30: svarka aparat | B30: 8.515999e+15 | C30: 3.5 | D30: Сварочный полуавтомат ХУГОНГ "NB 251K" Профессиональный многофункциональный сварочный аппарат. Оптимально подходит для сварки углеродистых, низколегированных и нержавеющих сталей. Сварочные процессы MIG/MAG, FCAW, MMA. Работа от однофазной сети 220В, сварка проволокой 0.6 - 1.2 мм. ОСОБЕННОСТИ МОДЕЛИ • Сварочный аппарат для полуавтоматической сварки в среде защитного газа (MIG/MAG) и ручной дуговой сварки (ММА). • Инверторная технология на базе новейших IGBT транзисторов • Оптимально подходит для сварки углеродистых, низколегированных и нержавеющих сталей • Встроенный Горячий старт и Антизалипание электрода • Регулировка индуктивности • Режимы работы горелки 2Т/4Т • Дисплей сварочного тока • Дисплей сварочного напряжения • Встроенный 2-х роликовый подающий механизм • Скорость подачи проволоки 2.5-13 м/мин • Функция дожига провоолоки • Функция автоматической постпродувки, 3 секунды • Быстроразъемное соединение сварочных кабелей • Быстроразъемное подключение защитного газа • Легкая смена полярности на панели управления • Встроенная защита от скачков напряжения • Встроенная термальная защита • Индикатор перегрева • Охлаждение с помощью встроенного вентилятора • Встроенный подающий механизм • Установка катушки весом до 20 кг • Кнопка протяжки проволоки • Розетка 36В для подогрева газа • Запатентованная технология, высокая мощность и продолжительность работы • Современный дизайн, небольшой вес, ручка для переноски ОБЩИЕ ХАРАКТЕРИСТИКИ РЕЖИМЫ СВАРКИ MIG/MAG, MMA НАПРЯЖЕНИЕ СЕТИ 220В ± 15% ПОТРЕБЛЕНИЕ МАКСИМАЛЬНОЕ, КВА 10.6 НАПРЯЖЕНИЕ ХОЛОСТОГО ХОДА, В 56 РЕГУЛИРОВКА СВАРОЧНОГО НАПРЯЖЕНИЯ ДЛЯ MIG, В 16.5-26.5 СВАРОЧНЫЙ ТОК MIG, А 50-250 ДИАМЕТР ПРОВОЛОКИ, ММ 0.6-1.2 МАССА КАТУШКИ, КГ 15/20 СВАРОЧНЫЙ ТОК ММА, А 50-200 ДИАМЕТР ЭЛЕКТРОДА, ММ 1.6-4 ПВ, % 60% (20°С) / 35% (40°С) КЛАСС ИЗОЛЯЦИИ F СТЕПЕНЬ ЗАЩИТЫ IP21S МАССА, КГ 23.2 ГАБАРИТНЫЕ РАЗМЕРЫ (Д;Ш;В; ММ) 510x243x492 МАССА БРУТТО, КГ 29 ГАБАРИТНЫЕ РАЗМЕРЫ УПАКОВКИ (Д;Ш;В; ММ) 635х350х530 ГАРАНТИЯ, СРОК (МЕС) 12
A31: Электр болгарка | B31: 846700200200 | C31: 2 | D31: Электропила Makita GA9020, невероятно долговечная, стойкая к перегреву, имеет усиленные конические шестерни редуктора, надежный и пылезащитный мотор (2200 Вт) для работы с бетономЭлектропила Makita GA9020, невероятно долговечная, стойкая к перегреву, имеет усиленные конические шестерни редуктора, надежный и пылезащитный мотор (2200 Вт) для работы с бетономЭлектропила Makita GA9020, невероятно долговечная, стойкая к перегреву, имеет усиленные конические шестерни редуктора, надежный и пылезащитный мотор (2200 Вт) для работы с бетономЭлектропила Makita GA9020, невероятно долговечная, стойкая к перегреву, имеет усиленные конические шестерни редуктора, надежный и пылезащитный мотор (2200 Вт) для работы с бетоном
A32: Электр перфоратор | B32: 0846700100200 | C32: 3 | D32: PowerMaxx BS Basic Set * Mobile Workshop (Аккумуляторная дрель-шуруповерт, мобильная мастерская) Напряжение аккумулятора:10.8 В Макс. мягкий крутящий момент:17 Нм Макс. жесткий крутящий момент:34 Нм Диаметр сверления в стали:10 мм д. сверления в мягкой древесине:18 ммPowerMaxx BS Basic Set * Mobile Workshop (Аккумуляторная дрель-шуруповерт, мобильная мастерская) Напряжение аккумулятора:10.8 В Макс. мягкий крутящий момент:17 Нм Макс. жесткий крутящий момент:34 Нм Диаметр сверления в стали:10 мм д. сверления в мягкой древесине:18 мм
A33: Электр дрел | B33: 08467001001000000 | C33: 2 | D33: PowerMaxx BS Basic Set * Mobile Workshop (Аккумуляторная дрель-шуруповерт, мобильная мастерская) Напряжение аккумулятора:10.8 В Макс. мягкий крутящий момент:17 Нм Макс. жесткий крутящий момент:34 Нм Диаметр сверления в стали:10 мм д. сверления в мягкой древесине:18 ммPowerMaxx BS Basic Set * Mobile Workshop (Аккумуляторная дрель-шуруповерт, мобильная мастерская) Напряжение аккумулятора:10.8 В Макс. мягкий крутящий момент:17 Нм Макс. жесткий крутящий момент:34 Нм Диаметр сверления в стали:10 мм д. сверления в мягкой древесине:18 мм
A34: Електр арра | B34: 0846700100300 | C34: 4 | D34: Пила Аллигатор: Конструкция ручная; Мощность 1700; Выходная мощность 900 Вт; Количество скоростей 1; Длина полотна 430 мм; Производительность; Размер хода 40 мм; Число ходов в минуту 3000; Дополнительная информация Комплект поставки; пильное полотно, ключ; Габариты (ШхВ) 918x219 мм; Вес 5.5 кгПила Аллигатор: Конструкция ручная; Мощность 1700; Выходная мощность 900 Вт; Количество скоростей 1; Длина полотна 430 мм; Производительность; Размер хода 40 мм; Число ходов в минуту 3000; Дополнительная информация Комплект поставки; пильное полотно, ключ; Габариты (ШхВ) 918x219 мм; Вес 5.5 кг
A35: Калитлар тўплами | B35: 8.204001e+15 | C35: 2 | D35: Количество в наборе: 122 единиц. - Насадки 1/2″: от 12 до 24мм, длиной 38 мм; от 27 до 32мм, длиной 42 мм. - Насадки 1/4″: от 4 до 14мм, длиной 25 мм. - Насадки 1/2″ длиние: от 10 до 19мм, длиной 76 мм. - Насадки 1/4″ длиние: от 4 до 9мм, длиной 50 мм. - Насадки Torx 1/2″: E10, E12, E14, E16, E18, E20, E22, E24. - Удлинители: 1/2″: 254 мм, 1/4″: 152 мм. - Кардан: 1/4″, 1/2. - Свечные головки 1/2″: 16 мм, 21 мм. - Трещотки: 1/2″ 255 мм, 1/4″ 155 мм, на 72 зуба. - Головки 1/4″ плоские: от 3 до 6 мм, длиной 25 мм. - Головки 1/4″ Pozidrive: Pz0, Pz1, PZ2, длиной 25 мм. - Головки 1/4″ Philips: PH0, PH1, PH2, длиной 25 мм. - Биты 1/4″ плоске: 4 мм, 5,5 мм, 6,5 мм, длиной 37 мм. - Биты 1/4″ Philips: PH1, PH2, PH3, длиной 37 мм. - Биты 1/4″ Pozidrive: PZ2, PZ3, длиной 37 мм. - Биты 1/4″ HEX: 3 мм, 4 мм, 5 мм, 6 мм, длиной 37 мм. - Биты 1/4″ TORX: T8, T10, T15, T20, T25, длиной 37 мм. - Биты 1/4″ TORX с отвестием: T10, T15, T20, T25, T40, длиной 37 мм. - Ключи комбинированные: от 8 до 19 мм. - Отвёртки плоские: 4x100мм, 6x150мм. - Отвёртки Philips: Ph2х100, Ph3х150мм. - Плоскогубцы: 180 мм. - Бокорезы: 160 мм. - Длинногубцы: 160 мм. - Клещи: 250 мм. - Молоток: 300 грамм. - Набор ключей шестигранных: от 2 мм, до 10 мм. - Материал: CrV. - Вес: 11,5 кг
A36: асалари оиласи | B36: 00199001008000000 | D36: Chetdan porodali zottor asalari oylalari uyalari bilan sotiladi asalarilar sog'lom va sifatli mahsuldor asal yig'adi asalarini sifatiga kafolat asalari onalari oq kraska bilan yelkasini metka qilingan shuningdek asalari uyalarini ham yaseymizChetdan porodali zottor asalari oylalari uyalari bilan sotiladi asalarilar sog'lom va sifatli mahsuldor asal yig'adi asalarini sifatiga kafolat asalari onalari oq kraska bilan yelkasini metka qilingan shuningdek asalari uyalarini ham yaseymizChetdan porodali zottor asalari oylalari uyalari bilan sotiladi asalarilar sog'lom va sifatli mahsuldor asal yig'adi asalarini sifatiga kafolat asalari onalari oq kraska bilan yelkasini metka qilingan shuningdek asalari uyalarini ham yaseymiz
A37: Issiqxona | B37: 940600100500 | D37: juda sifatli profil maxsulotidan tayyorlangan issiqxonalar 1 sotixdan katta barcha turdagi issiqxonalarni talabga qarab turli xil o`lchamlarda yayyorlab beramiz 4 lik profildan kurilgan juda sifatli profil maxsulotidan tayyorlangan issiqxonalar 1 sotixdan katta barcha turdagi issiqxonalarni talabga qarab turli xil o`lchamlarda yayyorlab beramiz 4 lik profildan kurilgan juda sifatli profil maxsulotidan tayyorlangan issiqxonalar 1 sotixdan katta barcha turdagi issiqxonalarni talabga qarab turli xil o`lchamlarda yayyorlab beramiz 4 lik profildan kurilgan juda sifatli profil maxsulotidan tayyorlangan issiqxonalar 1 sotixdan katta barcha turdagi issiqxonalarni talabga qarab turli xil o`lchamlarda yayyorlab beramiz 4 lik profildan kurilgan
A38: Oq qand | B38: 08438001020000000
A39: Oshxona idishlar | B39: 03924001010034011
A40: Ускуналар барча турдаги | B40: 9.031001e+15
A41: Бошқа мебеллар (барча турлари) | B41: 9.4030011e+15
A42: Болалар учун ўйинчоқ тўплар | B42: 09503018043000000
A43: Бошқа совутгичлар ветринний | B43: 8.418001e+15
...

Sheet Списка фирма
B1: № | F1: Махалла | H1: Дата | I1: Фирма номлари | J1: Директор | K1: Cчет | L1: Мфо | N1: инн | O1: парол | P1: Солик тури | Q1: под | R1: яс | S1: фойда | T1: Ккс | U1: Сув | V1: мол мулк | W1: мол натижа | X1: Баланс | Y1: стат | Z1: Каттий солик отказ | AA1: инкасса | AB1: Рестир | AC1: ijara shartnoma | AE1: Камерал тушган | AF1: хат
B2: =ROW()-1 -> 1 | F2: G'alaba mahallasi | H2: 41095 | I2: Saidnazar Shaxzodbek | J2: Saidjanov Shoxzodbek Saidnazarovich | K2: 20208000204987861001 | L2: 1125 | N2: 302341341 | O2: 11111111 | P2: яс | Q2: 1 | R2: 1
B3: =ROW()-1 -> 2 | F3: Bog'ot shaharchasi | H3: 43182 | I3: Bogot tomorqa xizmat | J3: "SAIDNAZAR-SHAXZODBEK" XK | K3: 20208000900863059001 | L3: 1125 | N3: 305426920 | P3: яс | Q3: 1 | R3: 1
B4: =ROW()-1 -> 3 | C4: Бола пули | E4: 1 | F4: Bog'ot shaharchasi | H4: 43817 | I4: TRITON MEGA LUX | J4: ORTIQOV SHOKIRBOY O‘KTAMBOYEVICH | K4: 20208000605157236001 | L4: 1125 | N4: 306954264 | P4: яс
B5: =ROW()-1 -> 4 | C5: камерал | D5: 54082 | F5: Oq Oltin mahallasi, | H5: 44040 | I5: Oq Oltinli Qaxramon tomoqa xizmat | J5: SAIDJONOV QAHRAMON BEKTURDIYEVICH | K5: 20208000505258701001 | L5: 401 | N5: 307599285 | O5: тугатилди | P5: яс
B6: =ROW()-1 -> 5 | E6: 1 | F6: Bo'ka mahallasi, | G6: Тугатилган | H6: 44671 | I6: Yetakchi tomoqa xizmat | J6: ORTIQOV SHOKIRBOY O‘KTAMBOYEVICH | K6: 20208000305528834001 | L6: 401 | N6: 309484665 | O6: 44707213 | P6: яс
B7: =ROW()-1 -> 6 | F7: Xunarmand mahallasi | H7: 44858 | I7: "INNAVATSION YASHIL MAKON" MCHJ | J7: VAISOV FURQAT FARHADOVICH | K7: 20208000605581989001 | L7: 556 | N7: 309965873 | O7: клуч | P7: яс
B8: =ROW()-1 -> 7 | F8: Qulonqorabog' QFY | H8: 44858 | I8: Хоразм бюк чинори | J8: BALTAYEV OZAD KOMILOVICH | K8: 20208000905592951001 | L8: 401 | N8: 309966397 | O8: клуч | P8: яс
B9: =ROW()-1 -> 8 | E9: 1 | F9: Obod mahallasi | H9: 44880 | I9: "SHEXMUROD 2022" MCHJ | J9: shermetov Maxsud Achilovich | K9: 20208000105587264001 | L9: 579 | N9: 310017573 | O9: 7 | P9: яс | Q9: 1 | R9: 1
B10: =ROW()-1 -> 9 | F10: Obod mahallasi | H10: 44880 | I10: SHEXMUROD 0112 MCHJ | J10: Shermetov Maxsud Achilovich | K10: 20208000805587208001 | L10: 4 | N10: 310017637 | O10: 7 | P10: яс | Q10: 1 | R10: 1
B11: =ROW()-1 -> 10 | D11: Баланс мото | F11: Oq Oltin mahallasi, | H11: 44917 | I11: BOG'OT MOTO HOUSE 007 MCHJ | J11: Mavlonov Rahmatjon Ollayor o'g'li | K11: 20208000905598744001 | L11: 401 | N11: 310108634 | O11: 80540173 | P11: яс | Q11: 1 | R11: 1
B12: =ROW()-1 -> 11 | D12: Муаммо озод | F12: Oq Oltin mahallasi, | H12: 44943 | I12: BOG'OT TEXNIKA OLAMI 01 MCHJ | J12: BALTAYEV OZAD KOMILOVICH | K12: 20208000105606343001 | L12: 1183 | N12: 310152827 | O12: клуч | P12: яс
B13: =ROW()-1 -> 12 | D13: 59200 | F13: Oq Oltin mahallasi, | H13: 44983 | I13: FINANS MOTO TRADE MCHJ | J13: SAIDJONOV QAHRAMON BEKTURDIYEVICH | K13: 20208000305618798001 | L13: 579 | N13: 310266408 | O13: 11111111 | P13: яс | Q13: 1 | R13: 1
B14: =ROW()-1 -> 13 | C14: измен факт | D14: Баланс мотти | E14: 1 | F14: Oq Oltin mahallasi | H14: 45010 | I14: SUPER MOTO 100 | J14: SAIDJONOV QAHRAMON BEKTURDIYEVICH | K14: 20208000205628942001 | L14: 401 | N14: 310337674 | O14: 11111111 | P14: яс | Q14: 1 | R14: 1
B15: =ROW()-1 -> 14 | D15: Анвар Бекчанов | F15: Bozor mahallasi | H15: 45093 | I15: Bog`zor Armada motors | J15: RO`ZMATOV SHAHZODBEK ANVARBEK O`G`LI | K15: 20208000205672005001 | L15: 1037 | N15: 310572178 | P15: яс
A16: 45211 | B16: =ROW()-1 -> 15 | C16: тоза | D16: халкбанк | E16: куш | F16: Namuna mahallasi | H16: 45211 | I16: KORZINKA HAUSE 777 MCHJ | J16: MAVLANOV XUDOYSHUKUR OLLAYOR O‘G‘LI | K16: 20208000905705033001 | L16: 401 | N16: 310848125 | O16: клуч | P16: яс
A17: 45211 | B17: =ROW()-1 -> 16 | C17: тоза | E17: куш | F17: Bozor mahallasi | H17: 45211 | I17: GARDEN MOTORS MCHJ | J17: AMINOV KAMOLIDDIN BAXROMOVICH | K17: 20208000305705032001 | L17: 401 | N17: 310848140 | O17: 3Rz79VVo4w | P17: яс | Q17: 1 | R17: 1
A18: 45212 | B18: =ROW()-1 -> 17 | C18: тоза | E18: куш | F18: Bog'iston mahallasi | H18: 45212 | I18: GARDENS TRADE 101 MCHJ | J18: AMINOV KAMOLIDDIN BAXROMOVICH | K18: 20208000905705496001 | L18: 401 | N18: 310850780 | O18: v4r3v3CPM1 | P18: яс | Q18: 1 | R18: 1
A19: 45213 | B19: =ROW()-1 -> 18 | C19: тоза | E19: куш | F19: Bog'iston mahallasi | H19: 45213 | I19: "GARDENS TRADE OFFICE" MCHJ | J19: AMINOV KAMOLIDDIN BAXROMOVICH | K19: 20208000605705503001 | L19: 401 | N19: 310850844 | O19: AAaa123456 | P19: яс | Q19: 1 | R19: 1
A20: 17,10,2023 | B20: =ROW()-1 -> 19 | C20: тоза | D20: халкбанк | E20: там шарт | F20: To'pchi mahallasi | H20: 45216 | I20: GARDEN MARKET 111 | J20: MAVLANOV XUDOYSHUKUR OLLAYOR O`G`LI | K20: 20208000505706639001 | L20: 401 | N20: 310857691 | O20: 7 | P20: к | U20: 1 | V20: 1 | W20: 1 | X20: 1 | Z20: 1
A21: 20,10,2023 | B21: =ROW()-1 -> 20 | C21: тоза | E21: куш | F21: Oktepa mahallasi | G21: Тугатилган | H21: 45218 | I21: "OQ TEPA MOTORS" MCHJ | J21: MAVLANOV XUDOYSHUKUR OLLAYOR O`G`LI | K21: 20208000105707642001 | L21: 401 | N21: 310863400 | O21: 7 | P21: яс
B22: =ROW()-1 -> 21 | C22: тоза | E22: куш | F22: NURLI MASKAN | H22: 45243 | I22: "BEST MOTOTRANS" MCHJ | J22: MAVLONOV RAHMATJON OLLAYOR O`G`LI | K22: 20208000605716207001 | L22: 401 | N22: 310920986 | O22: 7 | P22: яс | Q22: клуч
B23: =ROW()-1 -> 22 | C23: тоза | E23: куш | F23: QALAJIQQALʻA | H23: 45244 | I23: "ARMADA EVRO MOTORS" MCHJ | J23: MAVLONOV RAHMATJON OLLAYOR O‘G‘LI | K23: 20208000205716767001 | L23: 401 | N23: 310924015 | O23: 7 | P23: яс | Q23: клуч
B24: =ROW()-1 -> 23 | C24: тоза | D24: 409 | E24: куш | F24: Obod mahallasi | H24: 45251 | I24: "TITANIUM MOTORS" MCHJ | J24: MAVLONOV RAHMATJON OLLAYOR O‘G‘LI | K24: 20208000905719578001 | L24: 401 | N24: 310940029 | P24: яс
B25: =ROW()-1 -> 24 | C25: Сотилди | D25: тугатилди | E25: куш | F25: АРБОБЛАР МФЙ | H25: 45271 | I25: "ARMADA CAMFORT MOTORS" MCHJ | J25: MAVLONOV RAHMATJON OLLAYOR O‘G‘LI | N25: 310974223 | P25: яс
B26: =ROW()-1 -> 25 | F26: Oq Oltin mahallasi | H26: 45376 | I26: ARMADA MOTORS 999 | J26: SAIDJANOV BEHZOD SAIDNAZAROVICH | N26: 311190978 | O26: 7 | P26: яс
B27: =ROW()-1 -> 26 | E27: сотилди | H27: 45666 | I27: PROFI NEX | J27: KARIMOV UMIRBEK | K27: 20208000207185396001 | L27: 491 | M27: Қорақалпоғистон | N27: 311820912 | O27: 11111111 | P27: к
B28: =ROW()-1 -> 27 | E28: сотилди | H28: 45677 | I28: BARAKA TEXNO DUNYO 777 | J28: MOVLANOV XUDASHUKUR | K28: 20208000107189367001 | L28: 491 | M28: Қорақалпоғистон | N28: 311846389 | O28: 20099666 | P28: к
B29: =ROW()-1 -> 28 | E29: шарт | H29: 45687 | I29: "ENERGIYA PANEL | J29: KARIMOV UMIRBEK | K29: 20208000107193587001 | L29: 1125 | N29: 311875306 | O29: 33391788 | P29: ккс | T29: 1
B30: =ROW()-1 -> 29 | E30: сотилди | H30: 45689 | I30: TEXHNO NEX | J30: SAIDJANOV BEHZOD SAIDNAZAROVICH | K30: 20208000107194156001 | L30: 450 | M30: Қорақалпоғистон | N30: 311881093 | P30: к
B31: =ROW()-1 -> 30 | E31: там шарт | H31: 45691 | I31: "TEXNO SPECIAL SERVIS | J31: SAIDJONOV QAHRAMON BEKTURDIYEVICH | K31: 20208000207194497001 | L31: 450 | M31: Қорақалпоғистон | N31: 311883827 | O31: 11111111 | P31: к | T31: 1 | Z31: 1
B32: =ROW()-1 -> 31 | E32: сотилди | H32: 45693 | I32: "OQ OLTIN BIZNES TADBIRKOR | J32: SAIDJOVOVA SABOXAT | K32: 20208000207195864001 | L32: 491 | M32: Қорақалпоғистон | N32: 311890834 | O32: 11111111 | P32: к
B33: =ROW()-1 -> 32 | C33: 80900 | D33: сотувда | E33: смарт | H33: 45695 | I33: SEVEN TEXNO MAX | J33: MOVLANOV XUDASHUKUR | K33: 20208000 | L33: 491 | M33: Қорақалпоғистон | N33: 311898482 | O33: 1111111 | P33: к
B34: =ROW()-1 -> 33 | E34: сотилди | H34: 45699 | I34: MEDIUM SALE | J34: SAIDJONOV QAHRAMON BEKTURDIYEVICH | K34: 20208000407199224001 | L34: 491 | M34: Қорақалпоғистон | N34: 311908509 | O34: 11111111 | P34: к
B35: =ROW()-1 -> 34 | E35: сотилди | H35: 45699 | I35: LIVESTOCK OF CATTLE | J35: MAVLANOV XUDOYSHUKUR OLLAYOR O‘G‘LI | K35: 20208000907199226001 | L35: 491 | M35: Қорақалпоғистон | N35: 311908548 | O35: 11111111 | P35: к
B36: =ROW()-1 -> 35 | E36: сотилди | H36: 45720 | I36: CONSTRUQTION CAPITAL TRADE | J36: SAIDJANOV BEHZOD SAIDNAZAROVICH | K36: 20208000007209411001 | L36: 491 | M36: Қорақалпоғистон | N36: 311960762 | O36: 11111111 | P36: к
B37: =ROW()-1 -> 36 | E37: сотилди | H37: 45727 | I37: TECHNICAL ACTIVE SERVICE | J37: SAIDJONOV QAHRAMON BEKTURDIYEVICH | K37: 20208000 | L37: 491 | M37: Қорақалпоғистон | N37: 311975158 | O37: 11111111 | P37: к
B38: =ROW()-1 -> 37 | D38: микрбанк | E38: сотилди | H38: 45731 | I38: CENTRAL CONSTRUCTION WORLD | J38: SAIDJOVOVA SABOXAT | K38: 20208000907214484001 | L38: 491 | M38: Қорақалпоғистон | N38: 311986974 | O38: 11111111 | P38: к
B39: =ROW()-1 -> 38 | C39: гитти | D39: сотувда | E39: там шарт | G39: M01851 | H39: 45736 | I39: STRATTON INVEST TEX | J39: MAVLANOV XUDOYSHUKUR OLLAYOR O`G`LI | K39: 20208000307217253001 | L39: 491 | M39: Қорақалпоғистон | N39: 312002021 | O39: 11111111 | P39: к
B40: =ROW()-1 -> 39 | C40: гитти | D40: сотувда | E40: там шарт | G40: MO1854 | H40: 45748 | I40: NEW BRIGHT CAPITAL | J40: SAIDJONOV QAHRAMON BEKTURDIYEVICH | K40: 20208000 | L40: 491 | M40: Қорақалпоғистон | N40: 312024445 | O40: 11111111 | P40: к
...

Sheet Лист6

Sheet с
A1: № | B1: январ | D1: феврвл | E1: март | F1: апрел | G1: май | H1: июн | I1: июл | J1: август | K1: сентябр | L1: октябр | M1: ноябр | N1: декабр | O1: жами
A2: 1 | B2: 5000000 | D2: 6500000 | E2: 6000000 | F2: =2000000+3000000+120000+100000+100000+680000 -> 6000000 | G2: 10000000 | H2: 9000000 | J2: =1000000+500000+1000000+100000+1000000+2400000 -> 6000000 | K2: =4000000+6500000 -> 10500000 | L2: =1500000+500000 -> 2000000 | M2: =1000000+1064000+900000+3000000 -> 5964000 | N2: =3500000+500000-800000 -> 3200000 | O2: =B2+D2+E2+F2+G2+H2+I2+J2+K2+L2+M2+N2-M2-N2 -> 61000000
A3: 2 | O3: =B3+D3+E3+F3+G3+H3+I3+J3+K3+L3+M3+N3 -> 0
A4: 3 | O4: =B4+D4+E4+F4+G4+H4+I4+J4+K4+L4+M4+N4 -> 0
A5: 4 | O5: =B5+D5+E5+F5+G5+H5+I5+J5+K5+L5+M5+N5 -> 0
A6: 5 | O6: =B6+D6+E6+F6+G6+H6+I6+J6+K6+L6+M6+N6 -> 0
A7: 6 | O7: =B7+D7+E7+F7+G7+H7+I7+J7+K7+L7+M7+N7 -> 0
D9: Расход
A10: сана | B10: Расход | G10: № | H10: прихот
A11: 46015 | B11: авария | C11: =265*12000+480000+420000 -> 4080000 | D11: Декабр ойлик | G11: 1 | H11: иш хакки подохот | I11: 460000 | J11: Гулом ога микра
G12: 2 | H12: иш хакки подохот | I12: 300000 | J12: Гулом ога микра
G13: 3 | H13: Ахмед ога бух | I13: 500000 | J13: Бух
G14: 4
G15: 5 | H15: иш хакки подохот | I15: 600000 | J15: Гулом ога мкб
G16: 6 | H16: иш хакки подохот | I16: 1000000 | J16: Бехзод ога Миллий банк
G17: 7
H18: Той | I18: 500000 | J18: Нозима апкам
K20: 45899 | N20: 28705000
N21: 9900000
C22: =SUM(C11:C21) -> 4080000
B24: Банк карздорлик
B25: Микро кредит банк | C25: =(16*350000)*0.24-900000 -> 444000 | D25: Эшон бува
B26: Халк Банк | C26: =(30*350000)*0.24+9442000+1512000-C27 -> 10174000
B27: Халк Банк | C27: 3300000
I45: =I44-I43 -> 0

Sheet сомпютер 
C2: Kompyuter
B3: Жуманазаов Тохир | C3: 7.5 | D3: Ғайрат дарча
B4: Садуллаева Гуламбой | C4: 7.5
B5: Худайберганов Ғанижон | C5: 7.5
B6: Жуманазаров Зафар | C6: 7.5
B7: Исмоилова Ойша | C7: 7.5 | D7: каримбой Сабез
B8: Аллаберганова Гулой | C8: 7.5 | D8: Темур машин
B9: Aminova Zeboxon | C9: 6.5
B10: Тоиров Сухроб | D10: Ренат ога шокир огани платигина 11.75 млн ташлаш керар
B11: Тоирова Матлуба
B12: Davletov Донёр | C12: 7.5 | D12: Азамат
B13: Кодирова Саида | C13: 7.5
B14: Рўзметова Рўзажон | C14: 7.5 | D14: Азамат
B15: Собиров Одамбой | C15: 7.5
B16: Жуманазарова Ўғилжон | C16: 7.5 | D16: Анвар ога
B17: Самандаров Жамшид | C17: 7.5 | D17: Анвар ога
B18: Худайназарова Момогул | C18: 7.5 | D18: Анвар ога
B19: Жуманиёзова Хилола | C19: 7.5 | D19: Анвар ога
B20: Алимбоев Камоладдин | C20: 7.5 | D20: 3.5 млн астака колди
B21: Алимбоева Рухсора | C21: 7.5
B22: Садуллаев Бобуржон | C22: 7.5 | D22: Farid oga
B23: Сапаев нурбек | C23: 7.5 | D23: azamat
B24: Садуллаев Содикжон | C24: 7.5 | D24: gulom mikra
B25: Тажиев Музаффар | C25: 7.5 | D25: Азамат
B26: Умаров Шодлик | C26: 7.5 | D26: Азамат
B27: Сабирова Назокат | C27: 7.5 | D27: Азамат
B28: Курaнбоева Мадина | C28: 5.8 | D28: Азамат
B29: Сотимбоева Нилуфар | C29: 7.5 | D29: Asad Xalq banki
B30: Султонова Махлиё | C30: 7.5 | D30: Азамат
B31: Сапаев Ойбек | C31: 7.5 | D31: Азамат
B32: Babajonova Soxiba | C32: 7.5 | D32: Азамат
B33: Мирзаева Матлуба | C33: 7.5 | D33: Даврон Доктор
... B35: Кушаев Расулбек | C35: 7.5 | D35: Rustam og`a usta mikra
B36: Кушаева Дилафруз | C36: 7.5
B37: Кушаева Гулшода | C37: 7.5
B38: Саидмуротова Зумрад | C38: 7.5 | D38: Ковунчи тошкент колхоз
B39: Турдиева Наргизахон | C39: 7.5 | D39: Сапаев Достон Боходирни укаси
B40: Бахрамова Дилфуза | C40: 6.7 | D40: урганчли апка
B41: Ахмадова Мохидил | C41: 7.5 | D41: Maqsad jura
B42: Бекчанова Анамой | C42: 7.5
...

Sheet Лист1
B4: firma nomi | C4: login | D4: parol | E4: pulniki
A5: 1 | B5: Oq oltin moto | C5: Oqoltinmoto | D5: 310215446 | E5: 500676 | CG5: 25
A6: 2 | B6: Kelajak | C6: 310203 | D6: 310203571 | E6: 521114 | CG6: 33
A7: 3 | B7: Future Moto line | C7: 310267 | D7: 310266415 | E7: 325679 | CG7: 24
A8: 4 | B8: Oq oltin moto trade | C8: 310266 | D8: 310266423 | E8: 513395 | CG8: 30
A9: 5 | B9: Shexmurod 1509 | C9: 310062915 | D9: 310062915 | E9: 477339 | CG9: 22
A10: 6 | B10: Shexmurod 0112 | C10: 310017637 | D10: 310017637 | E10: 142424 | CG10: 33
A11: 7 | B11: Chichila | C11: 7659 | D11: 77777777 | E11: 374351 | F11: 0 | H11: 0 | L11: 0 | N11: 0 | O11: 0 | R11: 0 | T11: 0 | V11: 0 | X11: 0 | Z11: 0 | AT11: 0 | AX11: 0 | BJ11: 0 | BN11: 0 | BP11: 0 | BR11: 0 | BT11: 0 | BV11: 0 | BX11: 0 | BY11: 53.6 | BZ11: 53.6 | CA11: 20.6 | CB11: 8.6 | CG11: 33
A12: 8 | B12: Super moto | C12: 7674 | D12: 310337674 | E12: 365788 | F12: 44 | H12: 44 | I12: =-42.3+22+22 -> 1.7 | J12: 42.3 | K12: 22 | L12: 20.3 | N12: 0 | O12: 0 | R12: 0 | T12: 0 | V12: 0 | X12: 0 | Z12: 0 | AL12: 0 | AM12: 0 | AT12: 0 | AX12: 0 | BB12: 0 | BH12: 0 | BJ12: 0 | BL12: 0 | BN12: 0 | BP12: 0 | BR12: 0 | BT12: 0 | BV12: 0 | BX12: 0 | BY12: 19.8 | BZ12: 19.8 | CA12: 19.8 | CB12: 19.8 | CG12: 33
A13: 9 | B13: Bog`ot kelajak moto | C13: 310401800 | D13: 310401800 | E13: 199050 | F13: 3 | H13: 3 | J13: 3 | L13: 3 | N13: 3 | O13: 0 | P13: 3 | R13: 3 | T13: 0 | V13: 0 | X13: 0 | Z13: 0 | AL13: 0 | AM13: 0 | AT13: 0 | AX13: 0 | BB13: 0 | BH13: 0 | BJ13: 0 | BL13: 0 | BN13: 0 | BP13: 0 | BR13: 0 | BT13: 0 | BV13: 0 | BX13: 0 | BZ13: 0 | CA13: 0 | CB13: 0 | CG13: 32 | CH13: 14 | CI13: 11 | CJ13: =324.8+8.8 -> 333.6 | CK13: 325 | CL13: 407 | CM13: 29.5 | CN13: 340 | CO13: 271.5 | CP13: 321.5 | CQ13: 5.5 | CR13: 5.5 | CS13: 5.5 | CT13: 5.5 | CU13: 5.5 | CV13: 364.5 | CW13: 23.4 | CX13: 173.4 | CY13: 163 | CZ13: 49.7 | DA13: 86.5 | DB13: 73.5 | DC13: 108.8 | DD13: 87.2 | DE13: 85.2 | DF13: 78 | DG13: 18 | DH13: 296 | DI13: 323.7 | DJ13: 620.6 | DK13: 7.3 | DL13: 8.1 | DM13: 34.3 | DN13: 241 | DO13: 100.4 | DP13: 132 | DQ13: 79.5 | DR13: 77.5 | DS13: 37.7 | DT13: 210 | DU13: 222.3 | DV13: 221.6 | DW13: 25.5 | DX13: 50.6 | DY13: 68.6 | DZ13: 142.7 | EA13: 224.4 | EB13: 11.8 | EC13: 9.2 | ED13: 41.6 | EE13: 49 | EF13: 20.1 | EG13: =155.7+5.7+276.4 -> 437.8 | EH13: =4.2+5.1+276.4 -> 285.7 | EI13: 289.4 | EK13: =+EH13-EI13 -> -3.7 | EM13: 5.5 | EN13: 5.5 | EO13: 5.5 | EP13: 5.5 | EQ13: 5.5 | ER13: 5.5 | ES13: 5.5 | ET13: 5.5 | EU13: 5.5 | EV13: 5.5 | EW13: 5.5 | EX13: 5.5 | EY13: 5.5 | EZ13: 5.5 | FA13: 5.5 | FB13: 5.5 | FC13: 5.5 | FD13: 5.5 | FE13: 5.5 | FF13: 5.5 | FG13: 5.5 | FH13: 5.5 | FI13: 5.5 | FJ13: 5.5 | FK13: 5.5 | FL13: 5.5 | FM13: 5.5 | FN13: 5.5 | FO13: 5.5 | FP13: 5.5 | FQ13: 5.5 | FR13: 5.5 | FS13: 5.5 | FT13: 5.5 | FU13: 5.2 | FV13: 5.5 | FW13: 5.5 | FX13: 5.5 | FY13: 5.5
A14: 10 | B14: Bog`ot lochin Armada moto MCHJ | C14: 310401792 | D14: 310401792 | E14: 569470 | F14: 0 | H14: 0 | I14: -6.3 | J14: 6.3 | L14: 0 | N14: 0 | O14: -4.7 | P14: 4.7 | R14: 4.7 | S14: =2.1+2.7 -> 4.8 | T14: 22 | V14: 22 | X14: 22 | Y14: 22 | Z14: 0 | AF14: 0 | AG14: =22-41 -> -19 | AH14: 19 | AL14: 0 | AM14: 0 | AT14: 22 | AX14: 0 | BB14: 0 | BF14: 0 | BH14: 0 | BJ14: 0 | BL14: 0 | BN14: 0 | BP14: 0 | BR14: 23 | BT14: 23 | BV14: 23 | BX14: 0 | BY14: 24 | BZ14: 24 | CA14: 24 | CB14: 24 | CG14: 32.9 | CH14: 3.1 | CI14: 2.1 | CJ14: 8.6 | CK14: 8.6 | CL14: 20.6 | CM14: 53.6 | CQ14: 7.2 | CR14: 7.2 | CS14: 7.2 | CT14: 7.2 | CU14: 7.2 | CY14: 6.2 | CZ14: 6.2 | DA14: 6.2 | DB14: 6.2 | DC14: 6.2 | DD14: 6.2 | DE14: 6.2 | DF14: 6.2 | DG14: 6.2 | DH14: 6.2 | DI14: 6.2 | DJ14: 6.2 | DK14: 6.2 | DL14: 6.2 | DM14: 6.2 | DN14: 6.2 | DO14: 6.2 | DP14: 6.2 | DQ14: 6.2 | DR14: 6.2 | DS14: 6.2 | DT14: 6.2 | DU14: 6.2 | DV14: 6.2 | DW14: 6.2 | DX14: 6.2 | DY14: 6.2 | DZ14: 6.2 | EA14: 6.2 | EB14: 6.2 | EC14: 6.2 | ED14: 6.2 | EE14: 6.2 | EF14: 6.2 | EG14: 6 | EH14: 6 | EI14: 6 | EK14: =+EH14-EI14 -> 0 | EM14: 7.2 | EN14: 7.2 | EO14: 7.2 | EP14: 7.2 | EQ14: 7.2 | ER14: 7.2 | ES14: 7.2 | ET14: 7.2 | EU14: 7.2 | EV14: 7.2 | EW14: 7.2 | EX14: 7.2 | EY14: 7.2 | EZ14: 7.2 | FA14: 7.2 | FB14: 7.2 | FC14: 7.2 | FD14: 7.2 | FE14: 7.2 | FF14: 7.2 | FG14: 7.2 | FH14: 7.2 | FI14: 7.2 | FJ14: 7.2 | FK14: 7.2 | FL14: 7.2 | FM14: 7.2 | FN14: 7.2 | FO14: 7.2 | FP14: 7.2 | FQ14: 7.2 | FR14: 7.2 | FS14: 7.2 | FT14: 7.2 | FU14: 7.2 | FV14: 7.2 | FW14: 7.2 | FX14: 7.2 | FY14: 7.2
A15: 11 | B15: ASHXABOD MOTOROLLER | C15: 310423741 | D15: 310423741 | E15: 194459 | F15: 0 | H15: 0 | J15: 0 | L15: 0 | N15: 0 | O15: -3.8 | P15: 3.85 | R15: 3.85 | T15: 0 | V15: 0 | X15: 0 | Z15: 0 | AA15: =20.4+5-25.2 -> 0.2 | AF15: 0 | AH15: 0 | AL15: 0 | AM15: 0 | AT15: 0 | AX15: 0 | BB15: 0 | BF15: 0 | BH15: 0 | BJ15: 0 | BL15: 0 | BN15: 0 | BP15: 0 | BR15: 24 | BS15: 24 | BT15: 0 | BV15: 0 | BX15: 0 | BY15: 66.4 | BZ15: 66.4 | CA15: 66.4 | CB15: 44.4 | CH15: 0.6 | CI15: 20.6 | CJ15: 19.8 | CK15: 19.8 | CL15: 19.8 | CM15: 19.8 | CO15: 23 | CP15: 23 | CQ15: 0.2 | CR15: 0.2 | CS15: 0.2 | CT15: 0.2 | CU15: 0.2 | CV15: 23 | CW15: 23 | CX15: 22 | CY15: 22 | DA15: 66 | DB15: 8.5 | DC15: 15.9 | DF15: 24.78 | DG15: 24.78 | DH15: 22 | DI15: 23 | DJ15: 24 | DK15: 24 | DL15: 6.8 | DM15: 22.5 | DN15: 15.75 | DO15: 8.25 | DP15: 38.25 | DQ15: 38.25 | DR15: 38.25 | DS15: 20.6 | DZ15: 22 | EA15: 22 | EB15: 3 | EC15: 3 | ED15: 2 | EE15: 20.3 | EF15: 42.3 | EG15: 44 | EH15: 44 | EI15: 44 | EK15: =+EH15-EI15 -> 0 | EM15: 0.2 | EN15: 0.2 | EO15: 0.2 | EP15: 0.2 | EQ15: 0.2 | ER15: 0.2 | ES15: 0.2 | ET15: 0.2 | EU15: 0.2 | EV15: 0.2 | EW15: 0.2 | EX15: 0.2 | EY15: 0.2 | EZ15: 0.2 | FA15: 0.2 | FB15: 0.2 | FC15: 0.2 | FD15: 0.2 | FE15: 0.2 | FF15: 0.2 | FG15: 0.2 | FH15: 0.2 | FI15: 0.2 | FJ15: 0.2 | FK15: 0.2 | FL15: 0.2 | FM15: 0.2 | FN15: 0.2 | FO15: 0.2 | FP15: 0.2 | FQ15: 0.2 | FR15: 0.2 | FS15: 0.2 | FT15: 0.2 | FU15: 0.2 | FV15: 0.2 | FW15: 0.2 | FX15: 0.2 | FY15: 0.2
A16: 12 | B16: Bog`ot Motoroller | C16: 310423575 | D16: 310423575 | E16: 643178 | F16: 2 | H16: 2 | J16: 2 | L16: 2 | N16: 2 | P16: 2 | R16: 2 | T16: 0 | V16: 0 | X16: 0 | Y16: -21.9 | Z16: 21.9 | AF16: 0 | AH16: 0 | AJ16: 0 | AL16: 0 | AN16: 0 | AT16: 0 | AV16: 0 | AX16: 0 | AZ16: 0 | BB16: 0 | BD16: 0 | BF16: 0 | BH16: 0 | BJ16: 0 | BL16: 0 | BM16: -22 | BN16: 22 | BP16: 22 | BR16: 0 | BS16: =24-33.9 -> -9.9 | BT16: 10 | BV16: 10 | BX16: 5.7 | BZ16: 5.7 | CA16: 5.7 | CB16: 55.7 | CH16: 24 | CI16: 24 | CJ16: 24 | CK16: 24 | CL16: 24 | CM16: 24 | CQ16: 4.5 | CR16: 4.5 | CS16: 4.5 | CT16: 4.5 | CU16: 4.5 | DA16: 50 | DC16: 23 | DD16: 19 | DE16: 19 | DF16: 32.2 | DG16: 20 | DH16: 16.7 | DI16: 97.5 | DJ16: 66.25 | DK16: 66.25 | DL16: 10 | DM16: 33 | DN16: 22 | DO16: 33.3 | DP16: 32 | DQ16: 32 | DR16: 32 | DX16: 21.9 | DY16: 22 | DZ16: 15 | EA16: 48 | EB16: 4.7 | EC16: 4.7 | ED16: 3 | EE16: 3 | EF16: 3 | EG16: 3 | EH16: 3 | EI16: 3 | EK16: =+EH16-EI16 -> 0 | EM16: 4.5 | EN16: 4.5 | EO16: 4.5 | EP16: 4.5 | EQ16: 4.5 | ER16: 4.5 | ES16: 4.5 | ET16: 4.5 | EU16: 4.5 | EV16: 4.5 | EW16: 4.5 | EX16: 4.5 | EY16: 4.5 | EZ16: 4.5 | FA16: 4.5 | FB16: 4.5 | FC16: 4.5 | FD16: 4.5 | FE16: 4.5 | FF16: 4.5 | FG16: 4.5 | FH16: 4.5 | FI16: 4.5 | FJ16: 4.5 | FK16: 4.5 | FL16: 4.5 | FM16: 4.5 | FN16: 4.5 | FO16: 4.5 | FP16: 4.5 | FQ16: 4.5 | FR16: 4.5 | FS16: 4.5 | FT16: 4.5 | FU16: 4.5 | FV16: 4.5 | FW16: 4.5 | FX16: 4.5 | FY16: 4.5
A17: 13 | B17: Bagat gold drakon | F17: 8.25 | H17: 0 | I17: -8.25 | J17: 8.25 | L17: 8.25 | N17: 8.3 | P17: 7.5 | R17: 0 | T17: 0 | V17: 0 | X17: =+Y17+Z17 -> 0 | Y17: -16.5 | Z17: 16.5 | AA17: =8.25+8.25 -> 16.5 | AB17: 0 | AD17: 0 | AF17: 38.25 | AG17: =8.25-16.5+8.25+15+15 -> 30 | AH17: 8.25 | AI17: =8.25+45-30-30-9+8.25 -> -7.5 | AJ17: =8.25+7.5 -> 15.75 | AL17: 22.5 | AM17: =7.5+8.25 -> 15.75 | AN17: 6.8 | AP17: 0.25 | AQ17: =8.25*5-41 -> 0.25 | AR17: 0 | AS17: =8.25+8.25+8.25+8.25+8.25+8.25+8.25-30-30-14.5 -> -16.75 | AT17: 16.7 | AU17: =8.25+8.25-30-11+8.25+8.25 -> -8 | AV17: 24.78 | AX17: 24.78 | AZ17: 0 | BB17: 15.9 | BC17: =8.25+8.25+8.25+8.25-11.3-10-20+8.25+7.5 -> 7.45 | BD17: 8.5 | BE17: =-66+8.25+8.25-8 -> -57.5 | BF17: 66 | BG17: 41.25 | BH17: 24.75 | BJ17: 0 | BL17: 0 | BN17: 40.53 | BP17: 24.75 | BR17: 0 | BT17: 0 | BV17: 0 | BX17: 16.5 | BZ17: 16.5 | CA17: 8.3 | CB17: 92 | CH17: 2.5 | CI17: 44 | CJ17: 44.4 | CK17: 44.4 | CL17: 66.4 | CM17: 66.4 | CQ17: 62.1 | CR17: 62.1 | CS17: 62.1 | CT17: 62.1 | CU17: 62.1 | DA17: 24 | DB17: 23 | DC17: 23.8 | DF17: 32.2 | DH17: 33 | DI17: 22.4 | DJ17: 100.3 | DK17: 100.3 | DL17: 70 | DM17: 27.3 | DO17: 65.5 | DP17: 21.2 | DQ17: 21.2 | DR17: 21.2 | DX17: 16.5 | DY17: 38.6 | DZ17: 9 | EA17: 33 | EB17: 3.85 | EC17: 3.85 | ED17: 8.3 | EE17: 2 | EF17: 6.3 | EG17: 2 | EH17: 2 | EI17: 2 | EK17: =+EH17-EI17 -> 0 | EM17: 62.1 | EN17: 62.1 | EO17: 62.1 | EP17: 62.1 | EQ17: 62.1 | ER17: 62.1 | ES17: 62.1 | ET17: 62.1 | EU17: 62.1 | EV17: 62.1 | EW17: 62.1 | EX17: 62.1 | EY17: 62.1 | EZ17: 62.1 | FA17: 62.1 | FB17: 62.1 | FC17: 62.1 | FD17: 62.1 | FE17: 62.1 | FF17: 62.1 | FG17: 62.1 | FH17: 62.1 | FI17: 62.1 | FJ17: 62.1 | FK17: 62.1 | FL17: 62.1 | FM17: 62.1 | FN17: 62.1 | FO17: 62.1 | FP17: 62.1 | FQ17: 62.1 | FR17: 62.1 | FS17: 62.1 | FT17: 62.1 | FU17: 62.1 | FV17: 62.1 | FW17: 62.1 | FX17: 62.1 | FY17: 62.1
A18: =+A17+1 -> 14 | B18: Soxibkor motoroller | C18: 310453508 | D18: 310453508 | E18: 168969 | F18: 0 | G18: 0 | H18: 0 | I18: -22 | J18: 22 | K18: 22 | L18: 22 | M18: 22 | N18: 21 | O18: =-28.1+21 -> -7.1 | P18: 28.1 | Q18: 24 | R18: 4.1 | S18: 4.1 | T18: 0 | V18: 0 | X18: =+Y18+Z18 -> 0 | Y18: =-15-5 -> -20 | Z18: 20 | AA18: 20 | AB18: 0 | AC18: 0 | AD18: 0 | AF18: 0 | AH18: 0 | AJ18: 0 | AL18: 33 | AM18: 33 | AN18: 0 | AO18: 0 | AP18: 0 | AR18: 0 | AT18: 0 | AV18: 0 | AW18: -32.2 | AX18: 32.2 | AY18: 31.71 | AZ18: 0.5 | BB18: 0.5 | BD18: 0.5 | BF18: 0.5 | BH18: 0.5 | BJ18: 0.5 | BL18: 0.5 | BM18: 0 | BN18: 0.5 | BP18: 0.5 | BQ18: -52 | BR18: 52.5 | BS18: =23-74+24+30-1.66 -> 1.34 | BT18: 51.2 | BU18: 33 | BV18: 18.2 | BX18: 0.2 | BY18: 69 | BZ18: =+CA18-CD18 -> 69.2 | CA18: 159.2 | CB18: 135.2 | CD18: 90 | CH18: 93.7 | CI18: 33.7 | CJ18: 55.7 | CK18: 55.7 | CL18: 5.7 | CM18: 5.7 | CN18: 5.7 | CO18: 10 | CP18: 10 | CQ18: 1 | CR18: 1 | CS18: 1 | CT18: 1 | CV18: 10 | CW18: 24 | CX18: 24.75 | CY18: 40.53 | DA18: 120.4 | DB18: 23.8 | DC18: 21.5 | DF18: 16.5 | DH18: 77 | DI18: 34.8 | DM18: 49.5 | DO18: 108.8 | DP18: 22.5 | DQ18: 22.5 | DR18: 22.5 | DX18: 20 | DZ18: 39.5 | EA18: 153.5 | EB18: 2 | EC18: 2 | ED18: 21 | EE18: 8.25 | EF18: 8.3 | EG18: 5 | EH18: 5 | EI18: 8.25 | EK18: =+EH18-EI18 -> -3.25
A19: =+A18+1 -> 15 | B19: shabnam | C19: 310453174 | D19: 310453174 | E19: 337796 | F19: 0 | G19: 0 | H19: 0 | I19: -11 | J19: 11 | K19: 11 | L19: 0 | N19: 0 | O19: -3.2 | P19: 3.2 | R19: 3.2 | S19: 3.2 | T19: 0 | V19: 0 | X19: 0 | Z19: 0 | AA19: 0 | AB19: 0 | AC19: 0 | AD19: 0 | AF19: 0 | AH19: 0 | AJ19: 0 | AL19: 0 | AM19: 0 | AN19: 0 | AO19: 0 | AP19: 24 | AQ19: 24 | AR19: 0 | AT19: 0 | AV19: 0 | AW19: -32.2 | AX19: 32.2 | AY19: 32.2 | AZ19: 0 | BB19: 0 | BD19: 0 | BF19: 50 | BH19: 0 | BI19: -50 | BJ19: 50 | BK19: 50 | BL19: 0 | BM19: 0 | BN19: 0 | BP19: 0 | BQ19: -32 | BR19: 32.04 | BS19: =25-1.66 -> 23.34 | BT19: 8.7 | BU19: -200 | BV19: 209 | BW19: 100 | BX19: =24+BZ19 -> 190 | BZ19: =+CA19+CC19-CD19 -> 166 | CA19: 211 | CB19: 111.9 | CC19: =21+24 -> 45 | CD19: 90 | CH19: 116 | CI19: 92 | CJ19: 92 | CK19: 92 | CL19: 8.3 | CM19: 16.5 | CN19: 16.5 | CO19: 18.2 | CP19: 51.2 | CQ19: 25 | CR19: 25 | CS19: 25 | CT19: 25 | CU19: 25 | CV19: 51.2 | CW19: 52.5 | CX19: 0.5 | CY19: 0.5 | DA19: 30.2 | DB19: 21.5 | DC19: 97.3 | DD19: 52.3 | DE19: 52.3 | DF19: 21.5 | DO19: 19 | DP19: 83.7 | DQ19: 83.7 | DR19: 83.7 | DX19: 76 | DZ19: 76.5 | EB19: 4.1 | EC19: 7.5 | ED19: 29.9 | EE19: 22 | EF19: 2 | EI19: 4.5 | EK19: =+EH19-EI19 -> -4.5 | EM19: 25 | EN19: 25 | EO19: 25 | EP19: 25 | EQ19: 25
A20: =+A19+1 -> 16 | B20: largo | C20: 310455544 | D20: 310455544 | E20: 845517 | F20: 0 | G20: 0 | H20: 0 | I20: 0 | J20: 0 | L20: 0 | N20: 0 | O20: 0 | P20: 0 | R20: 0 | S20: 0 | T20: 0 | V20: 0 | X20: 0 | Z20: 0 | AA20: 0 | AB20: 0 | AC20: 0 | AD20: 0 | AF20: 0 | AH20: 0 | AJ20: 0 | AL20: 0 | AM20: 0 | AN20: 0 | AO20: 0 | AP20: 0 | AR20: 0 | AT20: 0 | AV20: 0 | AW20: -16.5 | AX20: 16.5 | AY20: -2.5 | AZ20: 19 | BB20: 23 | BD20: 23 | BE20: =-24+23 -> -1 | BF20: 24 | BG20: 24 | BH20: 0 | BJ20: 0 | BL20: 0 | BM20: -25.9 | BN20: 25.9 | BP20: 25.9 | BQ20: 26 | BR20: 0 | BS20: -105.5 | BT20: 105.5 | BU20: =-100-100 -> -200 | BV20: 305.7 | BW20: 100 | BX20: =+BZ20-BY20 -> 250.5 | BY20: 10 | BZ20: =+CA20+CC20-CD20 -> 260.5 | CA20: 313.5 | CB20: 338.5 | CC20: =24+22+18+33 -> 97 | CD20: =100+50 -> 150 | CH20: 153.9 | CI20: 116 | CJ20: 135.2 | CK20: 135.2 | CL20: 159.2 | CM20: 69.2 | CN20: 0.2 | CO20: 209 | CP20: 8.7 | CQ20: 2.2 | CR20: 2.2 | CS20: 2.2 | CT20: 2.2 | CU20: 2.2 | CV20: 8.7 | CW20: 32.04 | CX20: 25.9 | CY20: 25.9 | DA20: 128 | DF20: 41.7 | EB20: 3.2 | EC20: 28.1 | ED20: 100 | EE20: 22 | EF20: 22 | EI20: 19.6 | EK20: =+EH20-EI20 -> -19.6 | EM20: 2.2 | EN20: 2.2 | EO20: 2.2 | EP20: 2.2 | EQ20: =2.2+17.5 -> 19.7 | ER20: 19.7 | ES20: 19.5 | ET20: =2.2+17.5 -> 19.7 | EU20: 19.7 | EV20: 19.7 | EW20: 19.7 | EX20: 19.7 | EY20: 19.7 | EZ20: 19.7 | FA20: 19.7 | FB20: 19.7 | FC20: 19.7 | FD20: 19.7 | FE20: 14.7 | FF20: 14.7 | FG20: 14.7 | FH20: 14.7 | FI20: 14.7 | FJ20: 14.7 | FK20: 14.7 | FL20: 14.7 | FM20: 14.7 | FN20: 14.7 | FO20: 14.7 | FP20: 14.7 | FQ20: 14.7 | FR20: 14.7 | FS20: 14.7 | FT20: 14.7 | FU20: 14.7 | FV20: 14.7 | FW20: 14.7 | FX20: 14.7 | FY20: 14.7
A21: =+A20+1 -> 17 | B21: oltinqum | C21: 310455536 | D21: 310455536 | E21: 317083 | F21: 0 | G21: 0 | H21: 0 | I21: 0 | J21: 0 | L21: 0 | N21: 0 | O21: -1.92 | P21: 1.92 | R21: 1.92 | S21: 1.959 | T21: 0 | V21: 0 | X21: 0 | Z21: 0 | AA21: 0 | AB21: 0 | AC21: 0 | AD21: 0 | AF21: 0 | AH21: 0 | AJ21: 0 | AL21: 0 | AM21: 0 | AN21: 0 | AO21: 0 | AP21: 0 | AQ21: 0 | AR21: 0 | AT21: 0 | AV21: 0 | AW21: -21.5 | AX21: 21.5 | AY21: =24-2.5 -> 21.5 | AZ21: 0 | BB21: 23.8 | BD21: 23.8 | BE21: =-59.8-59.8+23 -> -96.6 | BF21: 120.4 | BH21: 120.4 | BI21: =10+33 -> 43 | BJ21: 77.4 | BK21: 21 | BL21: 56.4 | BM21: =-59.8-59.8-26+28+28 -> -89.6 | BN21: 146 | BO21: =33+17+19.2 -> 69.2 | BP21: 76.8 | BQ21: =-22+24+22+6.5+24 -> 54.5 | BR21: =+BS21+BT21 -> 22.34 | BS21: =-60-1.66+24 -> -37.66 | BT21: 60 | BU21: =22+30-100 -> -48 | BV21: 108 | BW21: 100 | BX21: =+BZ21-BY21 -> 53 | BY21: =90+100 -> 190 | BZ21: 243 | CA21: 432.3 | CB21: 265.4 | CC21: =25+27+24 -> 76 | CD21: =250+15 -> 265 | CH21: 161 | CI21: 208 | CJ21: 111.9 | CK21: 111.9 | CL21: 211 | CM21: 166 | CN21: 190 | CO21: 305.7 | CP21: 105.5 | CQ21: 35 | CR21: 35 | CS21: 35 | CT21: 35 | CU21: 35 | CV21: 105.5 | CW21: 22.34 | CX21: 76.8 | CY21: 146 | CZ21: 56.4 | DA21: 155.3 | DF21: 22 | DG21: 87 | EB21: 2 | EC21: 3.2 | EF21: 11 | EK21: =+EH21-EI21 -> 0 | EM21: 35 | EN21: 35 | EO21: 35 | EP21: 35 | EQ21: 35 | ER21: 35 | ES21: 35 | ET21: 35 | EU21: 35 | EV21: 35 | EW21: 35 | EX21: 35 | EY21: 35 | EZ21: 35 | FA21: 35 | FB21: 35 | FC21: 35 | FD21: 36 | FE21: 36 | FF21: 36 | FG21: 36 | FH21: 36 | FI21: 36 | FJ21: 0
